Workbook

Sheet Active Employees
A1: Last name, First name | B1: Work Email | C1: Hire Date | D1: Job Information: Date | E1: Division | F1: Department | G1: Job Title | H1: Reporting to | I1: Team | J1: Sub Team
A2: Abaidoo, Larissa | B2: larissa.abaidoo@docker.com | C2: 45426 | D2: 45888 | E2: Products | F2: PROD-Accounts & Billing | G2: Staff Product Manager | H2: Dave Morris | I2: Billing
A3: Abishai, Esther | B3: esther.abishai@docker.com | C3: 45272 | D3: 45870 | E3: Sales | F3: SLS-Solutions Engineering | G3: Sr Solutions Engineer, Enterprise | H3: Kevin Barfield | I3: SE
A4: Adcock, Nicholas | B4: nick.adcock@docker.com | C4: 43529 | D4: 45870 | E4: Engineering | F4: ENG-AI Cloud | G4: Sr Software Engineer | H4: Marko Papic | I4: Build Cloud
A5: Agodjro, Innell | B5: innell.agodjro@docker.com | C5: 45790 | D5: 45839 | E5: General & Administrative | F5: GA-People | G5: Sr People Partner | H5: Linda Tan
A6: Agrawal, Pooja | B6: pooja.agrawal@docker.com | C6: 45496 | D6: 45496 | E6: General & Administrative | F6: GA-Finance | G6: Sr Manager, FP&A | H6: Joe Becic
A7: Ahmed, Suhaib | B7: suhaib.ahmed@docker.com | C7: 45265 | D7: 45870 | E7: Marketing | F7: MKT-Marketing Ops | G7: Staff Data Engineer | H7: Trisha McCanna
A8: Ainsworth-Patrick, Christopher | B8: chris.ainsworth-patrick@docker.com | C8: 44649 | D8: 45870 | E8: Engineering | F8: ENG-SCS | G8: Staff Software Engineer | H8: Stéphanie Hertrich | I8: Secure Supply Chain
A9: Aizawa, Daisuke | B9: daisuke.aizawa@docker.com | C9: 45244 | D9: 45870 | E9: Sales | F9: SLS-MidEnterprise-EMEA | G9: Associate Account Executive, Mid-Enterprise | H9: Jay Goodman
A10: Albu, Andrei | B10: andrei.albu@docker.com | C10: 44768 | D10: 45870 | E10: Engineering | F10: ENG-DD & Core DX | G10: Manager, Engineering | H10: Chris Crone | I10: Release and Platform
A11: Albus, Roderick | B11: roderick.albus@docker.com | C11: 45482 | D11: 45482 | E11: Sales | F11: SLS-Enterprise-EMEA | G11: Sr Account Executive, Enterprise | H11: James Hammons | I11: Enterprise
A12: Aleyner, Elia | B12: Elia.Aleyner@docker.com | C12: 45280 | D12: 45870 | E12: Products | F12: PROD-General | G12: Head of Technical Alliances | H12: Mark Cavage
A13: Allen, Abigail | B13: abigail.allen@docker.com | C13: 45083 | D13: 45870 | E13: Sales | F13: SLS-Growth & Renewals | G13: Renewals Manager I | H13: Jon Stout | I13: Renewals
A14: Allen, John | B14: john.allen@docker.com | C14: 45908 | D14: 45908 | E14: Sales | F14: SLS-Channel | G14: Partner Sales Manager | H14: Aaron Morrison
A15: Allen, Mark | B15: mark.allen@docker.com | C15: 45412 | D15: 45870 | E15: Sales | F15: SLS-Solutions Engineering | G15: Solutions Engineer, Strategic | H15: Kevin Barfield | I15: Solutions Engineers
A16: Allsopp, Patricia | B16: trish.allsopp@docker.com | C16: 44607 | D16: 45231 | E16: General & Administrative | F16: GA-People | G16: Lead, Recruiting Operations | H16: Breanna Paredes
A17: Alonso, Javier | B17: javier.alonso@docker.com | C17: 44950 | D17: 45870 | E17: Products | F17: PROD-Product Design | G17: Staff Product Designer | H17: Earl Carlson | I17: Performance and Stability
A18: AlSaif, Manal | B18: manal.alsaif@docker.com | C18: 45223 | D18: 45870 | E18: Products | F18: PROD-Product Design | G18: Sr Product Designer | H18: Earl Carlson | I18: Core Experiences
A19: Alvarez, Kevin | B19: kevin.alvarez@docker.com | C19: 44368 | D19: 45870 | E19: Engineering | F19: ENG-DD & Core DX | G19: Staff Software Engineer | H19: Shaun Thompson | I19: Core Components
A20: Amandong, Ashime | B20: ashime.ashime@docker.com | C20: 44615 | D20: 45870 | E20: Customer Success | F20: CS-Support | G20: Sr Solutions Architect | H20: Walker McCandrew | I20: CS Enablement
A21: Amarendiran, Kavindira | B21: kavindira.amarendiran@docker.com | C21: 45098 | D21: 45870 | E21: Customer Success | F21: CS-Support | G21: Sr Sustaining Engineer | H21: Gagan Arora | I21: Sustaining Engineers
A22: Angeles, Jennifer | B22: jennifer.angeles@docker.com | C22: 45006 | D22: 45870 | E22: Marketing | F22: MKT-Product Marketing | G22: Sr Manager, Enablement GTM | H22: Nikhil Kaul
A23: Anhalt, Fabienne | B23: fabienne.anhalt@docker.com | C23: 45916 | D23: 45916 | E23: Engineering | F23: ENG-SCS | G23: Software Engineer II | H23: Elliot Rushton
A24: Ani, Eileen | B24: eileen.ani@docker.com | C24: 44775 | D24: 45870 | E24: Products | F24: PROD-Product Design | G24: Director, Product Design | H24: Tushar Jain
A25: Arora, Gagan | B25: gagan.arora@docker.com | C25: 44979 | D25: 45870 | E25: Customer Success | F25: CS-Support | G25: Sr Manager, Sustaining Engineering | H25: Jerry Baker | I25: Sustaining Engineers
A26: Asim, Ozair | B26: ozair.asim@docker.com | C26: 45195 | D26: 45870 | E26: Engineering | F26: ENG-SCS | G26: Sr Software Engineer | H26: Stéphanie Hertrich | I26: Registry
A27: Aslam, Zubair | B27: zubair.aslam@docker.com | C27: 45132 | D27: 45870 | E27: Sales | F27: SLS-Solutions Engineering | G27: Principal Solutions Manager | H27: Andrew Muollo | I27: SE
A28: Axsom, Shawn | B28: shawn.axsom@docker.com | C28: 44102 | D28: 45888 | E28: Engineering | F28: ENG-Accounts & Billing | G28: Director, Engineering | H28: Dave Morris | I28: Billing
A29: Ayub, John | B29: john.ayub@docker.com | C29: 45441 | D29: 45870 | E29: Marketing | F29: MKT-Product Marketing | G29: Staff Product Marketing Manager | H29: Nikhil Kaul
A30: Azevedo, Hugo | B30: hugo.azevedo@docker.com | C30: 45426 | D30: 45870 | E30: Sales | F30: SLS-Solutions Engineering | G30: Sr Solutions Engineer, Enterprise | H30: Kevin Barfield | I30: SE
A31: Azhar, Maxime | B31: maxime.azhar@docker.com | C31: 44796 | D31: 45870 | E31: Sales | F31: SLS-Growth & Renewals | G31: Sr Renewals Manager II | H31: Jon Stout | I31: Renewals
A32: Baker, Jerry | B32: jerry.baker@docker.com | C32: 44144 | D32: 45870 | E32: Customer Success | F32: CS-Support | G32: Director, Support | H32: Dixie Dunn | I32: Support
A33: Ballback, Stacee | B33: stacee.ballback@docker.com | C33: 44439 | D33: 45894 | E33: Marketing | F33: MKT-Growth Marketing | G33: Sr Global Integrated Campaigns Manager | H33: Maria Johnson
A34: Barfield, Kevin | B34: kevin.barfield@docker.com | C34: 45028 | D34: 45870 | E34: Sales | F34: SLS-Solutions Engineering | G34: Director, Solution Engineers | H34: Cody Green | I34: Solutions Architects
A35: Barker, Christopher | B35: chris.barker@docker.com | C35: 45741 | D35: 45870 | E35: Sales | F35: SLS-Solutions Engineering | G35: Sr Solutions Engineer, Enterprise | H35: Kevin Barfield | I35: Solutions Engineers
A36: Barnaby, Allison | B36: allison.barnaby@docker.com | C36: 45230 | D36: 45870 | E36: Sales | F36: SLS-MidEnterprise-NA | G36: Sr Manager, Mid Enterprise East | H36: Tyler Kluempke
A37: Basnayake, Sadeepa | B37: tharinda.basnayake@docker.com | C37: 44502 | D37: 45870 | E37: Sales | F37: SLS-TAM | G37: Technical Account Manager | H37: Maja Chapus | I37: Customer Advisory Team
A38: Baumgartner, Edwin | B38: scott.baumgartner@docker.com | C38: 43916 | D38: 45701 | E38: General & Administrative | F38: GA-Finance | G38: CFO | H38: Don Johnson
A39: Becic, Joseph | B39: joe.becic@docker.com | C39: 43291 | D39: 45047 | E39: General & Administrative | F39: GA-Finance | G39: Director, Finance | H39: Scott Baumgartner
A40: Beck, Nicolas | B40: nicolas.beck@docker.com | C40: 44748 | D40: 45870 | E40: Engineering | F40: ENG-AI Cloud | G40: Sr Software Engineer | H40: Ivan Curkovic | I40: Build Cloud
...

Sheet Cloudflare
A1: Work Email | B1: roles | C1: Reviewed by: | D1: Downgraded Permissions or Removed (If disabled for 90+ days, please remove) | E1: Notes | F1: Active Employee | G1: VLOOKUP
A2: aaron.solomon@docker.com | B2: Billing, Analytics | F2: No | G2: =VLOOKUP(A2,'Active Employees'!$B$2:$B$498,1,false) -> #N/A
A3: karan.vohra@docker.com | B3: Super Administrator - All Privileges | F3: No | G3: =VLOOKUP(A3,'Active Employees'!$B$2:$B$498,1,false) -> #N/A
A4: alex.hokanson@docker.com | B4: Super Administrator - All Privileges | F4: Yes | G4: =VLOOKUP(A4,'Active Employees'!$B$2:$B$498,1,false) -> alex.hokanson@docker.com
A5: silvin.lubecki@docker.com | B5: Administrator Read Only | F5: Yes | G5: =VLOOKUP(A5,'Active Employees'!$B$2:$B$498,1,false) -> silvin.lubecki@docker.com
A6: romain.belorgey@docker.com | B6: Super Administrator - All Privileges | F6: Yes | G6: =VLOOKUP(A6,'Active Employees'!$B$2:$B$498,1,false) -> romain.belorgey@docker.com
A7: james.braden@docker.com | B7: Super Administrator - All Privileges, Administrator | F7: Yes | G7: =VLOOKUP(A7,'Active Employees'!$B$2:$B$498,1,false) -> james.braden@docker.com
A8: ozair.asim@docker.com | B8: Administrator Read Only | F8: Yes | G8: =VLOOKUP(A8,'Active Employees'!$B$2:$B$498,1,false) -> ozair.asim@docker.com
A9: jeff.carter@docker.com | B9: Super Administrator - All Privileges, Administrator | F9: Yes | G9: =VLOOKUP(A9,'Active Employees'!$B$2:$B$498,1,false) -> jeff.carter@docker.com
A10: stephanie.hertrich@docker.com | B10: Super Administrator - All Privileges | F10: Yes | G10: =VLOOKUP(A10,'Active Employees'!$B$2:$B$498,1,false) -> stephanie.hertrich@docker.com
A11: vincent.damery@docker.com | B11: Administrator Read Only | F11: Yes | G11: =VLOOKUP(A11,'Active Employees'!$B$2:$B$498,1,false) -> vincent.damery@docker.com
A12: gabriele.dibernardo@docker.com | B12: Administrator Read Only | F12: Yes | G12: =VLOOKUP(A12,'Active Employees'!$B$2:$B$498,1,false) -> gabriele.dibernardo@docker.com
A13: shelton.graves@docker.com | B13: Administrator Read Only | F13: Yes | G13: =VLOOKUP(A13,'Active Employees'!$B$2:$B$498,1,false) -> shelton.graves@docker.com
... A21: kyle.trantham@docker.com | B21: Administrator Read Only | F21: Yes | G21: =VLOOKUP(A21,'Active Employees'!$B$2:$B$498,1,false) -> kyle.trantham@docker.com
A22: infra+cloudflare@docker.com | B22: Super Administrator - All Privileges | G22: =VLOOKUP(A22,'Active Employees'!$B$2:$B$498,1,false) -> #N/A

Sheet Github - Docker
A1: login | B1: name | C1: is_public | D1: role | E1: saml_name_id | F1: Reviewed by: | G1: Downgraded Permissions or Removed (If disabled for 90+ days, please remove) | H1: Notes | I1: VLOOKUP | J1: Active Employee
A2: brentseaton92 | C2: FALSE | D2: Owner | E2: brent_seaton@docker.com | I2: Contractor | J2: Yes
A3: cdupuis | B3: Christian Dupuis | C3: FALSE | D3: Owner | E3: christian.dupuis@docker.com | I3: =VLOOKUP(E3,'Active Employees'!$B$2:$B$498,1,false) -> christian.dupuis@docker.com | J3: Yes
A4: chris-crone | B4: Chris Crone | C4: TRUE | D4: Owner | E4: christopher.crone@docker.com | I4: =VLOOKUP(E4,'Active Employees'!$B$2:$B$498,1,false) -> christopher.crone@docker.com | J4: Yes
A5: danwschultz | B5: Dan Schultz | C5: FALSE | D5: Owner | E5: daniel.schultz@docker.com | I5: =VLOOKUP(E5,'Active Employees'!$B$2:$B$498,1,false) -> daniel.schultz@docker.com | J5: Yes
A6: fjmcs | B6: Fiona McShane | C6: FALSE | D6: Owner | E6: fiona.mcshane@docker.com | I6: =VLOOKUP(E6,'Active Employees'!$B$2:$B$498,1,false) -> fiona.mcshane@docker.com | J6: Yes
A7: ipedrazas | B7: Ivan Pedrazas | C7: FALSE | D7: Owner | E7: ivan.pedrazas@docker.com | I7: =VLOOKUP(E7,'Active Employees'!$B$2:$B$498,1,false) -> ivan.pedrazas@docker.com | J7: Yes
A8: jeanlaurent | B8: Jean-Laurent de Morlhon | C8: TRUE | D8: Owner | E8: jeanlaurent@docker.com | I8: =VLOOKUP(E8,'Active Employees'!$B$2:$B$498,1,false) -> jeanlaurent@docker.com | J8: Yes
A9: jeffreystrauss | B9: Jeff Strauss | C9: FALSE | D9: Owner | E9: jeffrey.strauss@docker.com | I9: =VLOOKUP(E9,'Active Employees'!$B$2:$B$498,1,false) -> jeffrey.strauss@docker.com | J9: Yes
A10: masegraye | B10: Mase Graye | C10: FALSE | D10: Owner | E10: mason.graye@docker.com | I10: =VLOOKUP(E10,'Active Employees'!$B$2:$B$498,1,false) -> mason.graye@docker.com | J10: Yes
A11: neilprosser | B11: Neil Prosser | C11: FALSE | D11: Owner | E11: neil.prosser@docker.com | I11: =VLOOKUP(E11,'Active Employees'!$B$2:$B$498,1,false) -> neil.prosser@docker.com | J11: Yes
A12: nfdocker | B12: Nate Fitch | C12: FALSE | D12: Owner | E12: nate.fitch@docker.com | I12: =VLOOKUP(E12,'Active Employees'!$B$2:$B$498,1,false) -> nate.fitch@docker.com | J12: Yes
A13: nicks | B13: Nick Santos | C13: FALSE | D13: Owner | E13: nick.santos@docker.com | I13: =VLOOKUP(E13,'Active Employees'!$B$2:$B$498,1,false) -> nick.santos@docker.com | J13: Yes
A14: shawnaxsom | B14: Shawn Axsom | C14: FALSE | D14: Owner | E14: shawn.axsom@docker.com | I14: =VLOOKUP(E14,'Active Employees'!$B$2:$B$498,1,false) -> shawn.axsom@docker.com | J14: Yes
... A21: vallieres | B21: Alexandre Vallières-Lagacé | C21: FALSE | D21: Owner | E21: alexandre.valliereslagace@docker.com | I21: =VLOOKUP(E21,'Active Employees'!$B$2:$B$498,1,false) -> alexandre.valliereslagace@docker.com | J21: Yes

Sheet Azure
A1: Tenant Name | B1: Scope Type | C1: Scope Name | D1: Work Email | E1: User Display Name | F1: Role Name | G1: Assignment Type | H1: Active Employee | I1: Reviewed by: | J1: Downgraded Permissions or Removed (If disabled for 90+ days, please remove) | K1: Notes | L1: VLOOKUP
A2: docker.co | B2: Azure AD Directory | C2: Directory-level | D2: okta.auth@dotcloud.onmicrosoft.com | E2: Okta Auth | F2: Knowledge Administrator | G2: Direct
A3: docker.co | B3: Azure AD Directory | C3: Directory-level | D3: okta.auth@dotcloud.onmicrosoft.com | E3: Okta Auth | F3: Virtual Visits Administrator | G3: Direct
A4: docker.co | B4: Azure AD Directory | C4: Directory-level | D4: okta.auth@dotcloud.onmicrosoft.com | E4: Okta Auth | F4: Exchange Recipient Administrator | G4: Direct
A5: docker.co | B5: Azure AD Directory | C5: Directory-level | D5: okta.auth@dotcloud.onmicrosoft.com | E5: Okta Auth | F5: Attribute Assignment Reader | G5: Direct
A6: docker.co | B6: Azure AD Directory | C6: Directory-level | D6: okta.auth@dotcloud.onmicrosoft.com | E6: Okta Auth | F6: Identity Governance Administrator | G6: Direct
A7: docker.co | B7: Azure AD Directory | C7: Directory-level | D7: okta.auth@dotcloud.onmicrosoft.com | E7: Okta Auth | F7: Customer LockBox Access Approver | G7: Direct
A8: docker.co | B8: Azure AD Directory | C8: Directory-level | D8: okta.auth@dotcloud.onmicrosoft.com | E8: Okta Auth | F8: Application Administrator | G8: Direct
A9: docker.co | B9: Azure AD Directory | C9: Directory-level | D9: okta.auth@dotcloud.onmicrosoft.com | E9: Okta Auth | F9: Windows 365 Administrator | G9: Direct
A10: docker.co | B10: Azure AD Directory | C10: Directory-level | D10: okta.auth@dotcloud.onmicrosoft.com | E10: Okta Auth | F10: Compliance Administrator | G10: Direct
A11: docker.co | B11: Azure AD Directory | C11: Directory-level | D11: okta.auth@dotcloud.onmicrosoft.com | E11: Okta Auth | F11: Edge Administrator | G11: Direct
A12: docker.co | B12: Azure AD Directory | C12: Directory-level | D12: okta.auth@dotcloud.onmicrosoft.com | E12: Okta Auth | F12: Exchange Administrator | G12: Direct
A13: docker.co | B13: Azure AD Directory | C13: Directory-level | D13: skalable.tech@docker.co | E13: Skalable | F13: Global Administrator | G13: Direct | H13: Contractor | L13: =VLOOKUP(D13,'Active Employees'!$B$2:$B$498,1,false) -> #N/A
A14: docker.co | B14: Azure AD Directory | C14: Directory-level | D14: okta.auth@dotcloud.onmicrosoft.com | E14: Okta Auth | F14: Cloud Device Administrator | G14: Direct | L14: =VLOOKUP(D14,'Active Employees'!$B$2:$B$498,1,false) -> #N/A
A15: docker.co | B15: Azure AD Directory | C15: Directory-level | D15: okta.auth@dotcloud.onmicrosoft.com | E15: Okta Auth | F15: Cloud App Security Administrator | G15: Direct | L15: =VLOOKUP(D15,'Active Employees'!$B$2:$B$498,1,false) -> #N/A
A16: docker.co | B16: Azure AD Directory | C16: Directory-level | D16: okta.auth@dotcloud.onmicrosoft.com | E16: Okta Auth | F16: Search Editor | G16: Direct | L16: =VLOOKUP(D16,'Active Employees'!$B$2:$B$498,1,false) -> #N/A
A17: docker.co | B17: Azure AD Directory | C17: Directory-level | D17: okta.auth@dotcloud.onmicrosoft.com | E17: Okta Auth | F17: Teams Devices Administrator | G17: Direct | L17: =VLOOKUP(D17,'Active Employees'!$B$2:$B$498,1,false) -> #N/A
A18: docker.co | B18: Azure AD Directory | C18: Directory-level | D18: okta.auth@dotcloud.onmicrosoft.com | E18: Okta Auth | F18: Attack Payload Author | G18: Direct | L18: =VLOOKUP(D18,'Active Employees'!$B$2:$B$498,1,false) -> #N/A
A19: docker.co | B19: Subscription | C19: Azure subscription 1 | D19: skalable.tech@docker.co | E19: Skalable | F19: User Access Administrator | G19: Direct | H19: Contractor | L19: =VLOOKUP(D19,'Active Employees'!$B$2:$B$498,1,false) -> #N/A
A20: docker.co | B20: Azure AD Directory | C20: Directory-level | D20: okta.auth@dotcloud.onmicrosoft.com | E20: Okta Auth | F20: External ID User Flow Administrator | G20: Direct | L20: =VLOOKUP(D20,'Active Employees'!$B$2:$B$498,1,false) -> #N/A
A21: docker.co | B21: Azure AD Directory | C21: Directory-level | D21: okta.auth@dotcloud.onmicrosoft.com | E21: Okta Auth | F21: License Administrator | G21: Direct | L21: =VLOOKUP(D21,'Active Employees'!$B$2:$B$498,1,false) -> #N/A
A22: docker.co | B22: Azure AD Directory | C22: Directory-level | D22: okta.auth@dotcloud.onmicrosoft.com | E22: Okta Auth | F22: Azure AD Joined Device Local Administrator | G22: Direct | L22: =VLOOKUP(D22,'Active Employees'!$B$2:$B$498,1,false) -> #N/A
A23: docker.co | B23: Azure AD Directory | C23: Directory-level | D23: okta.auth@dotcloud.onmicrosoft.com | E23: Okta Auth | F23: Attribute Definition Administrator | G23: Direct | L23: =VLOOKUP(D23,'Active Employees'!$B$2:$B$498,1,false) -> #N/A
A24: docker.co | B24: Azure AD Directory | C24: Directory-level | D24: okta.auth@dotcloud.onmicrosoft.com | E24: Okta Auth | F24: B2C IEF Keyset Administrator | G24: Direct | L24: =VLOOKUP(D24,'Active Employees'!$B$2:$B$498,1,false) -> #N/A
A25: docker.co | B25: Azure AD Directory | C25: Directory-level | D25: okta.auth@dotcloud.onmicrosoft.com | E25: Okta Auth | F25: Attribute Assignment Administrator | G25: Direct | L25: =VLOOKUP(D25,'Active Employees'!$B$2:$B$498,1,false) -> #N/A
A26: docker.co | B26: Azure AD Directory | C26: Directory-level | D26: okta.auth@dotcloud.onmicrosoft.com | E26: Okta Auth | F26: Directory Readers | G26: Direct | L26: =VLOOKUP(D26,'Active Employees'!$B$2:$B$498,1,false) -> #N/A
A27: docker.co | B27: Azure AD Directory | C27: Directory-level | D27: okta.auth@dotcloud.onmicrosoft.com | E27: Okta Auth | F27: SharePoint Administrator | G27: Direct | L27: =VLOOKUP(D27,'Active Employees'!$B$2:$B$498,1,false) -> #N/A
A28: docker.co | B28: Subscription | C28: Engineering Partnership Test | D28: skalable.tech@docker.co | E28: Skalable | F28: User Access Administrator | G28: Direct | H28: Contractor | L28: =VLOOKUP(D28,'Active Employees'!$B$2:$B$498,1,false) -> #N/A
A29: docker.co | B29: Subscription | C29: IAM Team | D29: skalable.tech@docker.co | E29: Skalable | F29: User Access Administrator | G29: Direct | H29: Contractor | L29: =VLOOKUP(D29,'Active Employees'!$B$2:$B$498,1,false) -> #N/A
A30: docker.co | B30: Azure AD Directory | C30: Directory-level | D30: okta.auth@dotcloud.onmicrosoft.com | E30: Okta Auth | F30: Azure DevOps Administrator | G30: Direct | L30: =VLOOKUP(D30,'Active Employees'!$B$2:$B$498,1,false) -> #N/A
A31: docker.co | B31: Azure AD Directory | C31: Directory-level | D31: okta.auth@dotcloud.onmicrosoft.com | E31: Okta Auth | F31: Kaizala Administrator | G31: Direct | L31: =VLOOKUP(D31,'Active Employees'!$B$2:$B$498,1,false) -> #N/A
A32: docker.co | B32: Azure AD Directory | C32: Directory-level | D32: okta.auth@dotcloud.onmicrosoft.com | E32: Okta Auth | F32: Insights Analyst | G32: Direct | L32: =VLOOKUP(D32,'Active Employees'!$B$2:$B$498,1,false) -> #N/A
A33: docker.co | B33: Azure AD Directory | C33: Directory-level | D33: okta.auth@dotcloud.onmicrosoft.com | E33: Okta Auth | F33: Insights Business Leader | G33: Direct | L33: =VLOOKUP(D33,'Active Employees'!$B$2:$B$498,1,false) -> #N/A
A34: docker.co | B34: Subscription | C34: IAM Team | D34: skalable.tech@docker.co | E34: Skalable | F34: User Access Administrator | G34: Direct | H34: Contractor | L34: =VLOOKUP(D34,'Active Employees'!$B$2:$B$498,1,false) -> #N/A
A35: docker.co | B35: Azure AD Directory | C35: Directory-level | D35: okta.auth@dotcloud.onmicrosoft.com | E35: Okta Auth | F35: Billing Administrator | G35: Direct | H35: Yes | L35: =VLOOKUP(D35,'Active Employees'!$B$2:$B$498,1,false) -> #N/A
A36: docker.co | B36: Subscription | C36: Sandbox | D36: skalable.tech@docker.co | E36: Skalable | F36: User Access Administrator | G36: Direct | H36: Contractor | L36: =VLOOKUP(D36,'Active Employees'!$B$2:$B$498,1,false) -> #N/A
A37: docker.co | B37: Subscription | C37: Security | D37: skalable.tech@docker.co | E37: Skalable | F37: User Access Administrator | G37: Direct | H37: Contractor | L37: =VLOOKUP(D37,'Active Employees'!$B$2:$B$498,1,false) -> #N/A
A38: docker.co | B38: Subscription | C38: Sustaining Engineering Team | D38: skalable.tech@docker.co | E38: Skalable | F38: User Access Administrator | G38: Direct | H38: Contractor | L38: =VLOOKUP(D38,'Active Employees'!$B$2:$B$498,1,false) -> #N/A
A39: docker.co | B39: Subscription | C39: Visual Studio Enterprise Subscription – MPN | D39: skalable.tech@docker.co | E39: Skalable | F39: User Access Administrator | G39: Direct | H39: Contractor | L39: =VLOOKUP(D39,'Active Employees'!$B$2:$B$498,1,false) -> #N/A
A40: docker.co | B40: Management Group | C40: Tenant Root Group | D40: skalable.tech@docker.co | E40: Skalable | F40: User Access Administrator | G40: Direct | H40: Contractor | L40: =VLOOKUP(D40,'Active Employees'!$B$2:$B$498,1,false) -> #N/A
...

Sheet AWS
A1: account_id | B1: account_name | C1: permission_set | D1: user_name | E1: group_name | F1: Reviewed by: | G1: Downgraded Permissions or Removed (If disabled for 90+ days, please remove) | H1: Notes | I1: VLOOKUP | J1: Active Employee
A2: 10438487392 | B2: Docker Data Stage | C2: Administrators | D2: gabriela.georgieva@docker.com | E2: AWSSSO_Administrators | I2: =VLOOKUP(D2,'Active Employees'!$B$2:$B$498,1,false) -> #N/A | J2: No
A3: 47302296459 | B3: Docker Security Tooling Stage | C3: Administrators | D3: gabriela.georgieva@docker.com | E3: AWSSSO_Administrators | I3: =VLOOKUP(D3,'Active Employees'!$B$2:$B$498,1,false) -> #N/A | J3: No
A4: 58264503038 | B4: Docker Image Signing - Stage | C4: Administrators | D4: gabriela.georgieva@docker.com | E4: AWSSSO_Administrators | I4: =VLOOKUP(D4,'Active Employees'!$B$2:$B$498,1,false) -> #N/A | J4: No
A5: 99407438094 | B5: Docker Platform Stage | C5: Administrators | D5: gabriela.georgieva@docker.com | E5: AWSSSO_Administrators | I5: =VLOOKUP(D5,'Active Employees'!$B$2:$B$498,1,false) -> #N/A | J5: No
A6: 111664719423 | B6: Docker Atomist | C6: Administrators | D6: gabriela.georgieva@docker.com | E6: AWSSSO_Administrators | I6: =VLOOKUP(D6,'Active Employees'!$B$2:$B$498,1,false) -> #N/A | J6: No
A7: 175142243308 | B7: Docker Sandbox | C7: Administrators | D7: gabriela.georgieva@docker.com | E7: AWSSSO_Administrators | I7: =VLOOKUP(D7,'Active Employees'!$B$2:$B$498,1,false) -> #N/A | J7: No
A8: 267155176707 | B8: Docker Security | C8: Administrators | D8: gabriela.georgieva@docker.com | E8: AWSSSO_Administrators | I8: =VLOOKUP(D8,'Active Employees'!$B$2:$B$498,1,false) -> #N/A | J8: No
A9: 277603989202 | B9: Docker Harmonia Root | C9: Administrators | D9: gabriela.georgieva@docker.com | E9: AWSSSO_Administrators | I9: =VLOOKUP(D9,'Active Employees'!$B$2:$B$498,1,false) -> #N/A | J9: No
A10: 300042230143 | B10: Docker Offload Customer Workloads - TIAA | C10: Administrators | D10: gabriela.georgieva@docker.com | E10: AWSSSO_Administrators | I10: =VLOOKUP(D10,'Active Employees'!$B$2:$B$498,1,false) -> #N/A | J10: No
A11: 303700122550 | B11: Docker Hub Stage | C11: Administrators | D11: gabriela.georgieva@docker.com | E11: AWSSSO_Administrators | I11: =VLOOKUP(D11,'Active Employees'!$B$2:$B$498,1,false) -> #N/A | J11: No
A12: 313121495448 | B12: Docker AtomicJar Control Plane | C12: Administrators | D12: gabriela.georgieva@docker.com | E12: AWSSSO_Administrators | I12: =VLOOKUP(D12,'Active Employees'!$B$2:$B$498,1,false) -> #N/A | J12: No
A13: 318510287843 | B13: Docker AtomicJar Business Workloads | C13: Administrators | D13: gabriela.georgieva@docker.com | E13: AWSSSO_Administrators | I13: =VLOOKUP(D13,'Active Employees'!$B$2:$B$498,1,false) -> #N/A | J13: No
... A577: 991137750147 | B577: Docker AWS Marketplace | C577: Administrators | D577: stefan.scherer@docker.com | E577: AWSSSO_Administrators | I577: =VLOOKUP(D577,'Active Employees'!$B$2:$B$498,1,false) -> stefan.scherer@docker.com | J577: Yes

Sheet GCP
A1: Email | B1: Scope Type | C1: Scope Name | D1: Scope ID | E1: Roles | F1: Assignment Type | G1: VLOOKUP | H1: Active Employee | I1: Notes | J1: Downgraded Permissions or Removed (If disabled for 90+ days, please remove)
A2: eddu@atomicjar.com | B2: Project | C2: Testcontainers OSS | D2: testcontainers-oss | E2: roles/owner | F2: Direct | G2: =VLOOKUP(A2,'Active Employees'!$B$2:$B$498,1,false) -> #N/A | H2: ? | I2: eddu.melendez@docker.com?
A3: kevin@atomicjar.com | B3: Project | C3: Testcontainers OSS | D3: testcontainers-oss | E3: roles/owner | F3: Direct | G3: =VLOOKUP(A3,'Active Employees'!$B$2:$B$498,1,false) -> #N/A | H3: ?
A4: brett.inman@docker.com | B4: Project | C4: docker-looker | D4: docker-looker | E4: roles/owner | F4: Direct | G4: =VLOOKUP(A4,'Active Employees'!$B$2:$B$498,1,false) -> #N/A | H4: No
A5: brett.inman@docker.com | B5: Project | C5: Ask Docker | D5: ask-docker | E5: roles/owner | F5: Direct | G5: =VLOOKUP(A5,'Active Employees'!$B$2:$B$498,1,false) -> #N/A | H5: No
A6: brett.inman@docker.com | B6: Project | C6: Dear Moby Extension | D6: dear-moby-extension | E6: roles/owner | F6: Direct | G6: =VLOOKUP(A6,'Active Employees'!$B$2:$B$498,1,false) -> #N/A | H6: No
A7: brett.inman@docker.com | B7: Project | C7: 1Password SCIM Bridge | D7: password-scim-bridge-360620 | E7: roles/owner | F7: Direct | G7: =VLOOKUP(A7,'Active Employees'!$B$2:$B$498,1,false) -> #N/A | H7: No
A8: brett.inman@docker.com | B8: Project | C8: FeatureFlags | D8: deep-lore-323516 | E8: roles/owner | F8: Direct | G8: =VLOOKUP(A8,'Active Employees'!$B$2:$B$498,1,false) -> #N/A | H8: No
A9: brett.inman@docker.com | B9: Project | C9: On-call automation | D9: mikes-on-call-automation | E9: roles/owner | F9: Direct | G9: =VLOOKUP(A9,'Active Employees'!$B$2:$B$498,1,false) -> #N/A | H9: No
A10: brett.inman@docker.com | B10: Project | C10: docker-oauth2proxy | D10: docker-oauth2proxy | E10: roles/owner | F10: Direct | G10: =VLOOKUP(A10,'Active Employees'!$B$2:$B$498,1,false) -> #N/A | H10: No
A11: brett.inman@docker.com | B11: Project | C11: cloudfront-bq | D11: cloudfront-bq | E11: roles/owner | F11: Direct | G11: =VLOOKUP(A11,'Active Employees'!$B$2:$B$498,1,false) -> #N/A | H11: No
A12: bryan.short@docker.com | B12: Project | C12: roadMapDiffGenerator | D12: roadmapdiffgenerator | E12: roles/owner | F12: Direct | G12: =VLOOKUP(A12,'Active Employees'!$B$2:$B$498,1,false) -> #N/A | H12: No
A13: colin.mcneil@docker.com | B13: Project | C13: Ask Docker | D13: ask-docker | E13: roles/bigquery.admin | F13: Direct | G13: =VLOOKUP(A13,'Active Employees'!$B$2:$B$498,1,false) -> #N/A | H13: No
A14: gianluca.brindisi@docker.com | B14: Project | C14: InfoSec Internal Apps | D14: infosec-internal-apps | E14: roles/owner | F14: Direct | G14: =VLOOKUP(A14,'Active Employees'!$B$2:$B$498,1,false) -> #N/A | H14: No
... A29: skalable.tech@docker.com | B29: Project | C29: My First Project | D29: manifest-campus-349917 | E29: roles/owner | F29: Direct | G29: =VLOOKUP(A29,'Active Employees'!$B$2:$B$498,1,false) -> #N/A | H29: No
A30: svc-google-pather-alerting@docker.com | B30: Project | C30: Panther Integration | D30: panther-integration-376501 | E30: roles/owner | F30: Direct | G30: =VLOOKUP(A30,'Active Employees'!$B$2:$B$498,1,false) -> #N/A | H30: No | I30: Assignment type mislabeled? Should be Service Account
A31: svc-midasbot@docker.com | B31: Project | C31: data-team | D31: data-team-231118 | E31: roles/editor | F31: Direct | G31: =VLOOKUP(A31,'Active Employees'!$B$2:$B$498,1,false) -> #N/A | H31: No | I31: Assignment type mislabeled? Should be Service Account
A32: tackle-service-gcp@tackle.io | B32: Project | C32: docker-public | D32: docker-public-445216 | E32: roles/owner | F32: Direct | G32: =VLOOKUP(A32,'Active Employees'!$B$2:$B$498,1,false) -> #N/A | H32: No | I32: Assignment type mislabeled? Should be Service Account
A33: thomas.psyhogeos@docker.com | B33: Project | C33: My First Project | D33: rare-gate-377301 | E33: roles/owner | F33: Direct | G33: =VLOOKUP(A33,'Active Employees'!$B$2:$B$498,1,false) -> #N/A | H33: No
A34: thomas.psyhogeos@docker.com | B34: Project | C34: k8sproject | D34: k8sproject-378311 | E34: roles/editor | F34: Direct | G34: =VLOOKUP(A34,'Active Employees'!$B$2:$B$498,1,false) -> #N/A | H34: No
A35: thomas.psyhogeos@docker.com | B35: Project | C35: My First Project | D35: emerald-vent-378714 | E35: roles/owner | F35: Direct | G35: =VLOOKUP(A35,'Active Employees'!$B$2:$B$498,1,false) -> #N/A | H35: No
A36: victor.bersy@docker.com | B36: Project | C36: Runtime Team | D36: runtime-team | E36: roles/owner | F36: Direct | G36: =VLOOKUP(A36,'Active Employees'!$B$2:$B$498,1,false) -> #N/A | H36: No
A37: zhelyazko.petrov@docker.com | B37: Project | C37: InfoSec Internal Apps | D37: infosec-internal-apps | E37: roles/owner | F37: Direct | G37: =VLOOKUP(A37,'Active Employees'!$B$2:$B$498,1,false) -> zhelyazko.petrov@docker.com | H37: No
A38: zhelyazko.petrov@docker.com | B38: Project | C38: Tines-GoogleSheet Integration | D38: valid-moment-385016 | E38: roles/owner | F38: Direct | G38: =VLOOKUP(A38,'Active Employees'!$B$2:$B$498,1,false) -> zhelyazko.petrov@docker.com | H38: No
A39: zhelyazko.petrov@docker.com | B39: Project | C39: Panther Integration | D39: panther-integration-376501 | E39: roles/owner | F39: Direct | G39: =VLOOKUP(A39,'Active Employees'!$B$2:$B$498,1,false) -> zhelyazko.petrov@docker.com | H39: No
A40: adm-brent_seaton@docker.com | B40: Project | C40: Chorus | D40: chorus-464720 | E40: roles/owner | F40: Direct | G40: =VLOOKUP(A40,'Active Employees'!$B$2:$B$498,1,false) -> #N/A | H40: Yes
A41: adm-brent_seaton@docker.com | B41: Project | C41: GAM Project | D41: gam-project-lmr3q | E41: roles/owner | F41: Direct | G41: =VLOOKUP(A41,'Active Employees'!$B$2:$B$498,1,false) -> #N/A | H41: Yes
A42: adm-brent_seaton@docker.com | B42: Project | C42: GAM Project | D42: gam-project-xb6-drw-v6z | E42: roles/owner | F42: Direct | G42: =VLOOKUP(A42,'Active Employees'!$B$2:$B$498,1,false) -> #N/A | H42: Yes
A43: ajeet_raina@docker.com | B43: Project | C43: Meetup-Demo | D43: meetup-demo-384606 | E43: roles/owner | F43: Direct | G43: =VLOOKUP(A43,'Active Employees'!$B$2:$B$498,1,false) -> #N/A | H43: Yes
A44: jamie_newell@docker.com | B44: Project | C44: Web Recaptcha | D44: web-recaptcha-396022 | E44: roles/editor | F44: Direct | G44: =VLOOKUP(A44,'Active Employees'!$B$2:$B$498,1,false) -> #N/A | H44: Yes
A45: alex.hokanson@docker.com | B45: Organization | C45: Organization 756105189467 | D45: 756105189467 | E45: roles/resourcemanager.organizationAdmin | F45: Direct | G45: =VLOOKUP(A45,'Active Employees'!$B$2:$B$498,1,false) -> alex.hokanson@docker.com | H45: Yes
A46: david.dooling@docker.com | B46: Organization | C46: Organization 756105189467 | D46: 756105189467 | E46: roles/resourcemanager.organizationAdmin | F46: Direct | G46: =VLOOKUP(A46,'Active Employees'!$B$2:$B$498,1,false) -> david.dooling@docker.com | H46: Yes
A47: james.braden@docker.com | B47: Organization | C47: Organization 756105189467 | D47: 756105189467 | E47: roles/resourcemanager.organizationAdmin | F47: Direct | G47: =VLOOKUP(A47,'Active Employees'!$B$2:$B$498,1,false) -> james.braden@docker.com | H47: Yes
A48: jeffrey.strauss@docker.com | B48: Organization | C48: Organization 756105189467 | D48: 756105189467 | E48: roles/billing.admin; roles/orgpolicy.policyAdmin; roles/resourcemanager.organizationAdmin; roles/resourcemanager.projectCreator; roles/resourcemanager.projectDeleter; roles/resourcemanager.projectMover | F48: Direct | G48: =VLOOKUP(A48,'Active Employees'!$B$2:$B$498,1,false) -> jeffrey.strauss@docker.com | H48: Yes
A49: robert.lorimer@docker.com | B49: Organization | C49: Organization 756105189467 | D49: 756105189467 | E49: roles/orgpolicy.policyAdmin; roles/resourcemanager.organizationAdmin | F49: Direct | G49: =VLOOKUP(A49,'Active Employees'!$B$2:$B$498,1,false) -> Robert.Lorimer@docker.com | H49: Yes
A50: shawn.shakir@docker.com | B50: Organization | C50: Organization 756105189467 | D50: 756105189467 | E50: roles/orgpolicy.policyAdmin; roles/resourcemanager.projectCreator | F50: Direct | G50: =VLOOKUP(A50,'Active Employees'!$B$2:$B$498,1,false) -> shawn.shakir@docker.com | H50: Yes
A51: abhi.singh@docker.com | B51: Project | C51: My First Project | D51: neon-glyph-389219 | E51: roles/owner | F51: Direct | G51: =VLOOKUP(A51,'Active Employees'!$B$2:$B$498,1,false) -> abhi.singh@docker.com | H51: Yes
A52: adm-daniel.schultz@docker.com | B52: Project | C52: Calm GCP Project | D52: calm-gcp-project | E52: roles/owner; roles/storage.admin | F52: Direct | G52: =VLOOKUP(A52,'Active Employees'!$B$2:$B$498,1,false) -> #N/A | H52: Yes
A53: adm-daniel.schultz@docker.com | B53: Project | C53: GAM Project | D53: gam-project-aa9-i1u-0ab | E53: roles/owner | F53: Direct | G53: =VLOOKUP(A53,'Active Employees'!$B$2:$B$498,1,false) -> #N/A | H53: Yes
A54: adm-daniel.schultz@docker.com | B54: Project | C54: GAM Project | D54: gam-project-xb6-drw-v6z | E54: roles/owner | F54: Direct | G54: =VLOOKUP(A54,'Active Employees'!$B$2:$B$498,1,false) -> #N/A | H54: Yes
...

Sheet Looker
A1: User Name | B1: User Email | C1: User Is Disabled (Yes / No) | D1: Is Active Employee | E1: User Created Date | F1: Last UI Login Date | G1: User Role Role List | H1: Notes
A2: Team Extensions Service Account | B2: guillaume.tardif+looker_service@docker.com | C2: No | D2: =COUNTIF('Active Employees'!B:B, B2) > 0 -> FALSE | E2: 44888 | F2: 1 | G2: Docker for Desktops Read Only,Gemini,Universal Viewer | H2: Login with API
A3: Looker Panther Service User | B3: panther-looker-integration@docker.com | C3: No | D3: =COUNTIF('Active Employees'!B:B, B3) > 0 -> FALSE | E3: 45113 | F3: 1 | G3: Gemini,Panther Logs Integration,Universal Viewer | H3: Login with API
A4: 0 | B4: svc-coefficient@docker.com | C4: No | D4: =COUNTIF('Active Employees'!B:B, B4) > 0 -> FALSE | E4: 45187 | F4: 1 | G4: Finance User,Gemini,Marketing SalesOps User,Product User | H4: Login with API | I4: Employees flag as FALSE are mostly external consultants
A5: Exit Script Service Account | B5: svc-exit-script+looker@docker.com | C5: No | D5: =COUNTIF('Active Employees'!B:B, B5) > 0 -> FALSE | E5: 45173 | F5: 1 | G5: Admin,Gemini,Universal Viewer | H5: Login with API
A6: Anecdotes User | B6: svc-infosec+anecdotes@docker.com | C6: No | D6: =COUNTIF('Active Employees'!B:B, B6) > 0 -> FALSE | E6: 45036 | F6: 1 | G6: Anecdotes Integration Role,Gemini,Universal Viewer | H6: Login with API
B7: temp_hackathon_service@docker.com | C7: No | D7: =COUNTIF('Active Employees'!B:B, B7) > 0 -> FALSE | E7: 45258 | F7: 1 | G7: Core Monitor User,Gemini,Universal Viewer | H7: Login with API
A8: Skalable Tech | B8: skalable.tech@docker.com | C8: No | D8: =COUNTIF('Active Employees'!B:B, B8) > 0 -> FALSE | E8: 44782 | F8: 44797 | G8: Gemini,ProductivRole,Universal Viewer
A9: Skalable Tech | B9: skalable.tech@docker.com | C9: No | D9: =COUNTIF('Active Employees'!B:B, B9) > 0 -> FALSE | E9: 44707 | F9: 45463 | G9: Gemini,ProductivRole,Universal Viewer
A10: JT Ibe | B10: jt.ibe@docker.com | C10: No | D10: =COUNTIF('Active Employees'!B:B, B10) > 0 -> FALSE | E10: 45027 | F10: 45480 | G10: Gemini,Universal Viewer
A11: Amn Rahman | B11: amn.rahman@docker.com | C11: No | D11: =COUNTIF('Active Employees'!B:B, B11) > 0 -> TRUE | E11: 43032 | F11: 45488 | G11: Admin,Central Data Dev,Central Data User,Core Monitor Dev,Core Monitor User,Gemini,Universal Viewer
A12: Luke Sowinski | B12: luke.sowinski@docker.com | C12: No | D12: =COUNTIF('Active Employees'!B:B, B12) > 0 -> TRUE | E12: 45519 | F12: 45520 | G12: Gemini,Universal Viewer
A13: Paweł Gronowski | B13: pawel.gronowski@docker.com | C13: No | D13: =COUNTIF('Active Employees'!B:B, B13) > 0 -> TRUE | E13: 45538 | F13: 45538 | G13: Gemini,Product User,Universal Viewer
A14: Jamie Newell | B14: jamie_newell@docker.com | C14: No | D14: =COUNTIF('Active Employees'!B:B, B14) > 0 -> FALSE | E14: 45544 | F14: 45544 | G14: Gemini,Universal Viewer
A15: Laurent Goderre | B15: laurent.goderre@docker.com | C15: No | D15: =COUNTIF('Active Employees'!B:B, B15) > 0 -> TRUE | E15: 45182 | F15: 45554 | G15: Gemini,Universal Viewer
A16: Derek McGowan | B16: derek.mcgowan@docker.com | C16: No | D16: =COUNTIF('Active Employees'!B:B, B16) > 0 -> TRUE | E16: 41962 | F16: 45575 | G16: Gemini,Product User
A17: Mahesan Param | B17: mahesan_param@docker.com | C17: No | D17: =COUNTIF('Active Employees'!B:B, B17) > 0 -> FALSE | E17: 45600 | F17: 45600 | G17: Gemini,Universal Viewer
A18: Nicole Tiu | B18: nicole_tiu@docker.com | C18: No | D18: =COUNTIF('Active Employees'!B:B, B18) > 0 -> FALSE | E18: 45600 | F18: 45601 | G18: Gemini,Universal Viewer
A19: Gabriele Di Bernardo | B19: gabriele.dibernardo@docker.com | C19: No | D19: =COUNTIF('Active Employees'!B:B, B19) > 0 -> TRUE | E19: 45300 | F19: 45617 | G19: Gemini,Universal Viewer
... A422: Yifeng Tek | B422: yifeng_tek@docker.com | C422: No | D422: =COUNTIF('Active Employees'!B:B, B422) > 0 -> FALSE | E422: 45600 | F422: 45933 | G422: Finance User,Gemini,Hub User,Marketing SalesOps Dev,Product Dev,Product User,Universal Viewer

Sheet Looker Admin
A1: Name | B1: Email | C1: Is Disabled (Yes / No) | D1: Role List | E1: Created Date | F1: Last Attempted UI Login Date | G1: Notes
A2: Exit Script Service Account | B2: svc-exit-script+looker@docker.com | C2: No | D2: Admin,Gemini,Universal Viewer | E2: 45173 | F2: 1 | G2: Login using API
A3: Amn Rahman | B3: amn.rahman@docker.com | C3: No | D3: Admin,Central Data Dev,Central Data User,Core Monitor Dev,Core Monitor User,Gemini,Universal Viewer | E3: 43032 | F3: 45488
A4: Ola Prokhorova | B4: oleksandra.prokhorova@docker.com | C4: No | D4: Admin,Central Data Dev,Gemini,Universal Viewer | E4: 45723 | F4: 45803
A5: Data Engineering | B5: data-engineering-team@docker.com | C5: No | D5: Admin,Core Monitor User,Gemini,Universal Viewer | E5: 45315 | F5: 45805
A6: Motoki Nakamura | B6: motoki.nakamura@docker.com | C6: No | D6: Admin,Central Data User,Core Monitor Dev,Core Monitor User,Gemini,Universal Viewer | E6: 44726 | F6: 45903
A7: Dave Morris | B7: dave.morris@docker.com | C7: No | D7: Admin,Gemini,Product User,Universal Viewer | E7: 45912 | F7: 45912
A8: Mike Kacherovich | B8: mikhail.kacherovich@docker.com | C8: No | D8: Admin,Central Data User,Core Monitor User,Finance User,Gemini,Marketing SalesOps User,Product User,Universal Viewer,User Plus System Activity | E8: 45212 | F8: 45913
A9: Tatia Markland | B9: tatia.markland@docker.com | C9: No | D9: Admin,Gemini,Universal Viewer | E9: 45609 | F9: 45917
A10: Merinne Mesku | B10: merinne.mesku@docker.com | C10: No | D10: Admin,Central Data Dev,Finance Dev,Gemini,Marketing SalesOps Dev,Product Dev,Universal Viewer | E10: 45527 | F10: 45922
A11: Nicola Watson | B11: nicola.watson@docker.com | C11: No | D11: Admin,Central Data Dev,Core Monitor Dev,DVP Dev,Finance User,Gemini,Marketing SalesOps User,Product Dev,Universal Viewer,User Plus System Activity | E11: 45062 | F11: 45926
A12: Dragos Georgescu | B12: dragos.georgescu@docker.com | C12: No | D12: Admin,Finance User,Gemini,Marketing SalesOps User,Product User,Universal Viewer | E12: 45482 | F12: 45929
A13: Paco Valverde | B13: paco.valverde@docker.com | C13: No | D13: Admin,Gemini,Hub User | E13: 44482 | F13: 45930
A14: Rob Burigo | B14: robert.burigo@docker.com | C14: No | D14: Admin,Central Data Dev,Finance Dev,Gemini,Marketing SalesOps Dev,Product Dev,Universal Viewer | E14: 45636 | F14: 45930
... A20: Abhi Singh | B20: abhi.singh@docker.com | C20: No | D20: Admin,Central Data Dev,Gemini,Universal Viewer | E20: 44782 | F20: 45933

Sheet Snowflake
A1: NAME | B1: EMAIL | C1: OWNER | D1: DEFAULT_ROLE | E1: ALL_ROLES | F1: LAST_SUCCESS_LOGIN | G1: Should Downgrade | H1: Should Delete | I1: Active Employee | J1: Notes | K1: Downgraded Permissions or Removed (If disabled for 90+ days, please remove)
A2: BHAGWINDER_PHUL | B2: bhagwinder.phul@docker.com | C2: USERADMIN | D2: PRODUCT_ANALYST | E2: PRODUCT_ANALYST | H2: Y | I2: =IF(COUNTIF('Active Employees'!B:B, B2)>0,"Y","N") -> Y | J2: Never logged in
A3: BRYAN_ENGLISH | B3: bryan.english@docker.com | C3: USERADMIN | D3: DOCKER_DESKTOP_READONLY | E3: DOCKER_DESKTOP_READONLY | H3: Y | I3: =IF(COUNTIF('Active Employees'!B:B, B3)>0,"Y","N") -> N | J3: Never logged in
A4: CHRIS_MCLELLAN | B4: chris.mclellan@docker.com | C4: USERADMIN | D4: PRODUCT_ANALYST | E4: PRODUCT_ANALYST | H4: Y | I4: =IF(COUNTIF('Active Employees'!B:B, B4)>0,"Y","N") -> Y | J4: Never logged in
A5: EDDU_MELENDEZ | B5: eddu.melendez@docker.com | C5: USERADMIN | D5: PRODUCTION_HUB_READONLY | E5: PRODUCTION_HUB_READONLY | H5: Y | I5: =IF(COUNTIF('Active Employees'!B:B, B5)>0,"Y","N") -> Y | J5: Never logged in
A6: JARRIS_WILKINS | B6: jarris.wilkins@docker.com | C6: SECURITYADMIN | D6: DOCKER_DEFAULT_READONLY | E6: DOCKER_DEFAULT_READONLY | H6: Y | I6: =IF(COUNTIF('Active Employees'!B:B, B6)>0,"Y","N") -> Y | J6: Never logged in
A7: JEAN_LAURENT | B7: jeanlaurent@docker.com | C7: ACCOUNTADMIN | D7: DOCKER_DEFAULT_READONLY | E7: DOCKER_DEFAULT_READONLY | H7: Y | I7: =IF(COUNTIF('Active Employees'!B:B, B7)>0,"Y","N") -> Y | J7: Never logged in
A8: JEFF_CARTER | B8: jeff.carter@docker.com | C8: USERADMIN | D8: PRODUCT_ANALYST | E8: PRODUCT_ANALYST | H8: Y | I8: =IF(COUNTIF('Active Employees'!B:B, B8)>0,"Y","N") -> Y | J8: Never logged in
A9: JONATHAN_STERNBERG | B9: jonathan.sternberg@docker.com | C9: USERADMIN | D9: DOCKER_DESKTOP_READONLY | E9: DOCKER_DESKTOP_READONLY | H9: Y | I9: =IF(COUNTIF('Active Employees'!B:B, B9)>0,"Y","N") -> Y | J9: Never logged in
A10: JOSH_NEWMAN | B10: josh.newman@docker.com | C10: USERADMIN | D10: DOCKER_DEFAULT_READONLY | E10: DOCKER_DEFAULT_READONLY | H10: Y | I10: =IF(COUNTIF('Active Employees'!B:B, B10)>0,"Y","N") -> Y | J10: Never logged in
A11: KATERINA_TOMRUSHKA | B11: katerina.tomrushka@docker.com | C11: USERADMIN | D11: PRODUCT_ANALYST | E11: PRODUCT_ANALYST | H11: Y | I11: =IF(COUNTIF('Active Employees'!B:B, B11)>0,"Y","N") -> Y | J11: Never logged in
A12: CHRIS_AINSWORTH | B12: chris.ainsworth-patrick@docker.com | C12: USERADMIN | D12: SALESOPS_ADMIN | E12: DOCKER_DEFAULT_READONLY, DVP_ADMIN, SALESOPS_ADMIN | F12: 2024-10-03 09:50:28.298 -0400 | I12: =IF(COUNTIF('Active Employees'!B:B, B12)>0,"Y","N") -> Y | J12: Login > 90 days ago
A13: OZAIR_ASIM | B13: ozair.asim@docker.com | C13: USERADMIN | D13: DOCKER_DEFAULT_READONLY | E13: DOCKER_DEFAULT_READONLY | F13: 2024-11-06 08:33:30.277 -0500 | I13: =IF(COUNTIF('Active Employees'!B:B, B13)>0,"Y","N") -> Y | J13: Login > 90 days ago
A14: JAMES_CHILDS | B14: james.childs@docker.com | C14: USERADMIN | D14: DOCKER_DEFAULT_READONLY | E14: BILLING_UNIFIED_CONSUMPTION, DOCKER_DEFAULT_READONLY | F14: 2024-11-12 13:29:07.112 -0500 | I14: =IF(COUNTIF('Active Employees'!B:B, B14)>0,"Y","N") -> Y | J14: Login > 90 days ago
A15: CHONGGHEE_LEE | B15: chongghee_lee@docker.com | C15: USERADMIN | D15: MARKETING_READONLY | E15: MARKETING_READONLY | F15: 2024-11-14 21:28:37.866 -0500 | H15: N | I15: =IF(COUNTIF('Active Employees'!B:B, B15)>0,"Y","N") -> N | J15: External consultant
A16: MISAEL_MOURA | B16: misael_moura@docker.com | C16: USERADMIN | D16: SF_NEOCOL_TEMP_ROLE | E16: SF_NEOCOL_TEMP_ROLE | F16: 2024-11-16 14:39:10.212 -0500 | H16: N | I16: =IF(COUNTIF('Active Employees'!B:B, B16)>0,"Y","N") -> N | J16: External consultant
A17: KAMARIAH_SAIFUL | B17: kamariah_saiful@docker.com | C17: USERADMIN | D17: MARKETING_READONLY | E17: MARKETING_READONLY | F17: 2024-11-17 20:30:05.937 -0500 | H17: N | I17: =IF(COUNTIF('Active Employees'!B:B, B17)>0,"Y","N") -> N | J17: External consultant
A18: IGNACIO_LOPEZLUNA | B18: ignacio.lopezluna@docker.com | C18: USERADMIN | D18: DOCKER_POWER_USER_READONLY | E18: DOCKER_DEFAULT_READONLY, DOCKER_POWER_USER_READONLY, TEST_CONTAINERS_READONLY | F18: 2024-12-18 09:19:54.428 -0500 | I18: =IF(COUNTIF('Active Employees'!B:B, B18)>0,"Y","N") -> Y | J18: Login > 90 days ago
A19: OLEG | B19: oleg.burov@docker.com | C19: USERADMIN | D19: DOCKER_DEFAULT_READONLY | E19: BILLING_UNIFIED_CONSUMPTION, DOCKER_DEFAULT_READONLY | F19: 2025-01-16 17:39:35.769 -0500 | I19: =IF(COUNTIF('Active Employees'!B:B, B19)>0,"Y","N") -> Y | J19: Login > 90 days ago
A20: BRYAN_CHAN | B20: bryan_chan@docker.com | C20: USERADMIN | D20: MARKETING_READONLY | E20: MARKETING_READONLY | F20: 2025-01-17 13:33:43.650 -0500 | H20: N | I20: =IF(COUNTIF('Active Employees'!B:B, B20)>0,"Y","N") -> N | J20: External consultant
A21: NICHOLAS_OREFICE | B21: nicholas.orefice@docker.com | C21: USERADMIN | D21: DOCKER_DEFAULT_READONLY | E21: DOCKER_DEFAULT_READONLY, SEGMENT_DESKTOP_READONLY | F21: 2025-01-17 15:05:27.527 -0500 | I21: =IF(COUNTIF('Active Employees'!B:B, B21)>0,"Y","N") -> Y | J21: Login > 90 days ago
A22: GABRIELE_DIBERNARDO | B22: gabriele.dibernardo@docker.com | C22: USERADMIN | D22: ARCHIVE_EVENTS_READONLY | E22: ARCHIVE_EVENTS_READONLY | F22: 2025-01-28 09:53:53.856 -0500 | I22: =IF(COUNTIF('Active Employees'!B:B, B22)>0,"Y","N") -> Y | J22: Login > 90 days ago
A23: JUSTIN_CORMACK | B23: justin.cormack@docker.com | C23: USERADMIN | D23: PRODUCT_ANALYST | E23: PRODUCT_ANALYST | F23: 2025-02-03 06:43:39.909 -0500 | H23: Y | I23: =IF(COUNTIF('Active Employees'!B:B, B23)>0,"Y","N") -> N | J23: Former employee
A24: SHAUN_THOMPSON | B24: shaun.thompson@docker.com | C24: USERADMIN | D24: DOCKER_POWER_USER_READONLY | E24: DOCKER_DEFAULT_READONLY, DOCKER_POWER_USER_READONLY | F24: 2025-02-10 16:22:39.661 -0500 | I24: =IF(COUNTIF('Active Employees'!B:B, B24)>0,"Y","N") -> Y | J24: Login > 90 days ago
A25: NICK_ADCOCK | B25: nick.adcock@docker.com | C25: USERADMIN | D25: DOCKER_DEFAULT_READONLY | E25: DOCKER_DEFAULT_READONLY | F25: 2025-02-24 12:22:25.380 -0500 | I25: =IF(COUNTIF('Active Employees'!B:B, B25)>0,"Y","N") -> Y | J25: Login > 90 days ago
A26: NICOLAS_DELOOF | B26: nicolas.deloof@docker.com | C26: USERADMIN | D26: SEGMENT_DESKTOP_READONLY | E26: SEGMENT_DESKTOP_READONLY | F26: 2025-02-26 04:55:57.617 -0500 | I26: =IF(COUNTIF('Active Employees'!B:B, B26)>0,"Y","N") -> Y | J26: Login > 90 days ago
A27: GEORGE_GABOLAEV | B27: georgii.gabolaev@docker.com | C27: SECURITYADMIN | D27: SEGMENT_DESKTOP_READONLY | E27: SEGMENT_DESKTOP_READONLY | F27: 2025-03-11 08:30:26.704 -0400 | I27: =IF(COUNTIF('Active Employees'!B:B, B27)>0,"Y","N") -> Y | J27: Login > 90 days ago
A28: DORIN_GEMAN | B28: dorin.geman@docker.com | C28: USERADMIN | D28: PRODUCT_ENGINEER_READONLY | E28: DOCKER_DESKTOP_READONLY, PRODUCT_ENGINEER__READONLY | F28: 2025-03-11 09:04:38.555 -0400 | I28: =IF(COUNTIF('Active Employees'!B:B, B28)>0,"Y","N") -> Y | J28: Login > 90 days ago
A29: AJITH_THILAKAN | B29: ajith.thilakan@docker.com | C29: USERADMIN | D29: DOCKER_DEFAULT_READONLY | E29: DOCKER_DEFAULT_READONLY | F29: 2025-03-16 22:07:18.085 -0400 | I29: =IF(COUNTIF('Active Employees'!B:B, B29)>0,"Y","N") -> Y | J29: Login > 90 days ago
A30: ALBERTO_GARCIA_HIERRO | B30: damaso.hierro@docker.com | C30: USERADMIN | D30: DOCKER_DEFAULT_READONLY | E30: DOCKER_DEFAULT_READONLY | F30: 2025-03-19 11:59:05.968 -0400 | I30: =IF(COUNTIF('Active Employees'!B:B, B30)>0,"Y","N") -> Y | J30: Login > 90 days ago
A31: MAT_WILSON | B31: mat.wilson@docker.com | C31: USERADMIN | D31: DOCKER_DEFAULT_READONLY | E31: DOCKER_DEFAULT_READONLY | F31: 2025-03-20 07:42:05.490 -0400 | I31: =IF(COUNTIF('Active Employees'!B:B, B31)>0,"Y","N") -> Y | J31: Login > 90 days ago
A32: JAVIER_GARCIA | B32: javier.garcia@docker.com | C32: USERADMIN | D32: DOCKER_POWER_USER_READONLY | E32: DOCKER_POWER_USER_READONLY | F32: 2025-03-20 07:46:04.204 -0400 | I32: =IF(COUNTIF('Active Employees'!B:B, B32)>0,"Y","N") -> Y | J32: Login > 90 days ago
A33: EKATERINA_TUGARINOVA | B33: ekaterina.tugarinova@docker.com | C33: USERADMIN | D33: DOCKER_DEFAULT_AND_WORKSPACES_READONLY | E33: DOCKER_DEFAULT_AND_WORKSPACES_READONLY, DOCKER_DEFAULT_READONLY | F33: 2025-03-26 11:07:40.438 -0400 | I33: =IF(COUNTIF('Active Employees'!B:B, B33)>0,"Y","N") -> Y | J33: Login > 90 days ago
A34: IVAN_PEDRAZAS | B34: ivan.pedrazas@docker.com | C34: USERADMIN | D34: DOCKER_DESKTOP_READONLY | E34: DOCKER_DEFAULT_READONLY, DOCKER_DESKTOP_READONLY | F34: 2025-04-09 13:06:45.142 -0400 | I34: =IF(COUNTIF('Active Employees'!B:B, B34)>0,"Y","N") -> Y | J34: Login > 90 days ago
A35: KAVINDIRA_AMARENDIRAN | B35: kavindira.amarendiran@docker.com | C35: SECURITYADMIN | D35: PRODUCTION_DESKTOP_READONLY | E35: PRODUCTION_DESKTOP_READONLY | F35: 2025-04-10 01:42:45.036 -0400 | I35: =IF(COUNTIF('Active Employees'!B:B, B35)>0,"Y","N") -> Y | J35: Login > 90 days ago
... A47: VINCENT_DAMERY | B47: vincent.damery@docker.com | C47: USERADMIN | D47: DOCKER_DEFAULT_READONLY | E47: DOCKER_DEFAULT_READONLY | F47: 2025-06-27 12:30:12.095 -0400 | I47: =IF(COUNTIF('Active Employees'!B:B, B47)>0,"Y","N") -> Y | J47: Login > 90 days ago
A48: FRANCESCO_CORTI | B48: francesco.corti@docker.com | C48: USERADMIN | D48: DOCKER_DEFAULT_READONLY | E48: DOCKER_DEFAULT_READONLY, DOCKER_DESKTOP_READONLY | F48: 2025-07-02 11:35:32.711 -0400 | I48: =IF(COUNTIF('Active Employees'!B:B, B48)>0,"Y","N") -> Y
A49: LUKE_BUNSELMEYER | B49: william.bunselmeyer@docker.com | C49: USERADMIN | D49: DOCKER_DEFAULT_READONLY | E49: DOCKER_DEFAULT_READONLY, DOCKER_DESKTOP_READONLY | F49: 2025-07-07 11:23:07.849 -0400 | I49: =IF(COUNTIF('Active Employees'!B:B, B49)>0,"Y","N") -> Y
A50: LUCAS_BERNALTE | B50: lucas.bernalte@docker.com | C50: USERADMIN | D50: CONSUMPTION_HUB_EXPERIENCES_ROLE | E50: CONSUMPTION_HUB_EXPERIENCES_ROLE, DOCKER_DEFAULT_READONLY | F50: 2025-07-10 03:25:52.634 -0400 | I50: =IF(COUNTIF('Active Employees'!B:B, B50)>0,"Y","N") -> Y
A51: SHELTON_GRAVES | B51: shelton.graves@docker.com | C51: SECURITYADMIN | D51: DOCKER_DEFAULT_READONLY | E51: DOCKER_DEFAULT_READONLY | F51: 2025-07-10 13:49:17.004 -0400 | I51: =IF(COUNTIF('Active Employees'!B:B, B51)>0,"Y","N") -> Y
...

Sheet Snowflake - SVC
A1: NAME | B1: TYPE | C1: OWNER | D1: DEFAULT_ROLE | E1: ALL_ROLES | F1: LAST_SUCCESS_LOGIN | G1: Should Delete | H1: Notes | I1: Downgraded Permissions or Removed (If disabled for 90+ days, please remove)
A2: AIRFLOW_SALESOPS_DEV | B2: SERVICE | C2: USERADMIN | D2: AIRFLOW_SALESOPS | E2: AIRFLOW_SALESOPS | G2: Y | H2: Never Used
A3: DEV_IDENTITY_GRAPH_USER | B3: SERVICE | C3: USERADMIN | D3: DEV_IDENTITY_GRAPH | E3: DEV_IDENTITY_GRAPH | F3: 2025-06-18 10:51:40.351 -0400
A4: AIRFLOW_MONITOR_USER_DEV | B4: SERVICE | C4: USERADMIN | E4: ACCOUNT_MONITOR | F4: 2025-07-07 17:03:59.627 -0400
A5: CONSUMPTION_MONITOR_USER | B5: LEGACY_SERVICE | C5: USERADMIN | D5: CONSUMPTION_MONITOR | E5: CONSUMPTION_MONITOR | F5: 2025-07-09 06:00:30.416 -0400
A6: PIGMENT_USER | B6: SERVICE | C6: USERADMIN | D6: PIGMENT | E6: PIGMENT | F6: 2025-07-09 14:32:39.949 -0400
A7: AIRFLOW_INFOSEC_EXPORT_DEV_USER | B7: SERVICE | C7: USERADMIN | D7: INFOSEC_EXPORT_DEV | E7: INFOSEC_EXPORT_DEV | F7: 2025-07-10 20:36:30.985 -0400
A8: CONSUMPTION_MONITOR_USER_PROD | B8: LEGACY_SERVICE | C8: USERADMIN | D8: CONSUMPTION_MONITOR_PROD | E8: CONSUMPTION_MONITOR_PROD | F8: 2025-07-14 06:00:30.699 -0400
A9: AIRFLOW_EVENTS_ADMIN_USER_DEV | B9: SERVICE | C9: USERADMIN | D9: EVENTS_ADMIN_STAGING | E9: EVENTS_ADMIN_STAGING | F9: 2025-07-21 11:00:03.074 -0400
A10: LOOKER_BAMBOOHR | B10: SERVICE | C10: SECURITYADMIN | D10: BAMBOOHR_READONLY | E10: BAMBOOHR_READONLY | F10: 2025-07-30 04:57:58.228 -0400
A11: LOOKER_PREVIEW_USER | B11: SERVICE | C11: USERADMIN | D11: LOOKER_PREVIEW_READONLY_ROLE | E11: LOOKER_PREVIEW_READONLY_ROLE, PRODUCTION_READ_ROLE | F11: 2025-07-30 06:53:51.879 -0400
A12: SNOWFLAKE_EXTENSIONS | B12: LEGACY_SERVICE | C12: USERADMIN | D12: SNOWFLAKE_EXTENSIONS_ADMIN | E12: SNOWFLAKE_EXTENSIONS_ADMIN | F12: 2025-08-11 03:53:55.481 -0400
A13: DBT_DEV_DEPLOYMENT_WORKSPACES_USER | B13: LEGACY_SERVICE | C13: USERADMIN | E13: DBT_DEPLOYMENTS_WORKSPACES | F13: 2025-08-12 15:00:10.909 -0400
A14: AIRFLOW_DVPP_USER_DEV | B14: LEGACY_SERVICE | C14: USERADMIN | D14: DVPP_STAGING | E14: DVPP_STAGING | F14: 2025-09-17 13:21:59.979 -0400
A15: MULESOFT_USER | B15: LEGACY_SERVICE | C15: USERADMIN | D15: MULESOFT_WRITE_ROLE | E15: CONSUMPTION_BILLING, MULESOFT_SANDBOX_WRITE_ROLE, MULESOFT_WRITE_ROLE | F15: 2025-09-18 06:00:17.014 -0400
A16: AEP_SERVICE_ACCOUNT | B16: SERVICE | C16: SECURITYADMIN | D16: AEP_SERVICE_ROLE | E16: AEP_SERVICE_ROLE | F16: 2025-09-24 06:27:38.505 -0400
A17: STAGING_DVP_DBT_USER | B17: LEGACY_SERVICE | C17: USERADMIN | D17: STAGING_DBT_DVP_DEPLOYMENTS | E17: DVP_DEV, STAGING_DBT_DVP_DEPLOYMENTS | F17: 2025-09-24 10:02:28.490 -0400
A18: ZAPIER_USER | B18: SERVICE | C18: USERADMIN | D18: ZAPIER_ROLE | E18: ZAPIER_ROLE | F18: 2025-09-25 10:43:06.647 -0400
A19: PROD_IDENTITY_GRAPH_USER | B19: LEGACY_SERVICE | C19: USERADMIN | D19: PROD_IDENTITY_GRAPH | E19: PROD_IDENTITY_GRAPH | F19: 2025-09-27 23:02:46.453 -0400
A20: GATO_SALES_RESEARCH_STAGE | B20: SERVICE | C20: USERADMIN | D20: GATO_SALES_RESEARCH_STAGE | E20: GATO_SALES_RESEARCH_STAGE | F20: 2025-10-01 17:44:28.804 -0400
A21: AIRFLOW_MONITOR_USER | B21: SERVICE | C21: USERADMIN | E21: ACCOUNT_MONITOR | F21: 2025-10-01 20:01:49.349 -0400
A22: CONSUMPTION_MONITOR_USER_STAGE | B22: LEGACY_SERVICE | C22: USERADMIN | D22: CONSUMPTION_MONITOR_STAGE | E22: CONSUMPTION_MONITOR_STAGE | F22: 2025-10-01 20:12:07.519 -0400
A23: GITHUB_ACTIONS_COREDATA_USER | B23: LEGACY_SERVICE | C23: USERADMIN | D23: COREDATA_GITHUB_BOT | E23: COREDATA_GITHUB_BOT | F23: 2025-10-01 21:28:15.512 -0400
A24: CENSUS | B24: LEGACY_SERVICE | C24: USERADMIN | D24: CENSUS_ROLE | E24: CENSUS_ROLE | F24: 2025-10-01 22:13:46.962 -0400
A25: AIRFLOW_DVPP_USER_PROD | B25: LEGACY_SERVICE | C25: USERADMIN | D25: DVPP_PROD | E25: DVPP_PROD | F25: 2025-10-02 00:09:06.664 -0400
A26: DDQM_INTEGRATION_ACCOUNT | B26: LEGACY_SERVICE | C26: USERADMIN | D26: DOCKER_DESKTOP_QUALITY_METRICS | E26: DOCKER_DESKTOP_QUALITY_METRICS | F26: 2025-10-02 05:01:09.662 -0400
A27: DATABRICKS_USER | B27: LEGACY_SERVICE | C27: USERADMIN | D27: PROD_DATABRICKS | E27: PROD_DATABRICKS | F27: 2025-10-02 05:02:31.734 -0400
A28: SIGMA_INCR_WH_USER | B28: SERVICE | C28: USERADMIN | D28: SIGMA_DATA_PROD | E28: SIGMA_DATA_PROD | F28: 2025-10-02 05:24:08.838 -0400
A29: GAINSIGHT | B29: LEGACY_SERVICE | C29: USERADMIN | D29: GAINSIGHT | E29: GAINSIGHT | F29: 2025-10-02 06:12:02.952 -0400
A30: AIRFLOW_WOOTRIC_USER_PROD | B30: LEGACY_SERVICE | C30: USERADMIN | D30: WOOTRIC_INGESTION_PROD | E30: WOOTRIC_INGESTION_PROD | F30: 2025-10-02 07:00:39.556 -0400
A31: SIGMA_COREDATA | B31: SERVICE | C31: USERADMIN | D31: SNOWFLAKE_MONITOR | E31: SNOWFLAKE_MONITOR | F31: 2025-10-02 07:24:10.703 -0400
A32: TEST_BI_GG_DEV | B32: LEGACY_SERVICE | C32: SECURITYADMIN | D32: DOCKER_DEFAULT_AND_WORKSPACES_READONLY | E32: DOCKER_DEFAULT_AND_WORKSPACES_READONLY, DOCKER_DESKTOP_READONLY | F32: 2025-10-02 08:01:39.874 -0400
A33: PREVIEW_AIRFLOW_DEPLOYMENTS | B33: SERVICE | C33: USERADMIN | D33: PREVIEW_AIRFLOW_DEPLOYMENTS | E33: PREVIEW_AIRFLOW_DEPLOYMENTS | F33: 2025-10-02 10:48:15.699 -0400
... A35: SIGMA_CS_USER | B35: SERVICE | C35: USERADMIN | D35: SIGMA_CS | E35: SIGMA_CS | F35: 2025-10-02 11:02:09.406 -0400
A36: DEV_DATA_DBT_USER | B36: LEGACY_SERVICE | C36: USERADMIN | E36: DEV_DBT_DEPLOYMENTS, ENGINEERING_DEV, MARKETING_ADMIN, MARKETING_DEV, PRODUCT_ANALYST, SALESOPS_DEV | F36: 2025-10-02 11:47:46.014 -0400
A37: SIGMA_APP_OWNER | B37: SERVICE | C37: USERADMIN | D37: SIGMA_APP_OWNER_ROLE | E37: SIGMA_APP_OWNER_ROLE | F37: 2025-10-02 11:49:35.088 -0400
A38: SIGMA_DEV_USER | B38: SERVICE | C38: USERADMIN | D38: SIGMA_DATA_DEV | E38: SIGMA_DATA_DEV | F38: 2025-10-02 12:51:26.968 -0400
A39: DBT_PROD_DEPLOYMENT_WORKSPACES_USER | B39: LEGACY_SERVICE | C39: USERADMIN | D39: DBT_PROD_DEPLOYMENTS_WORKSPACES_ROLE | E39: DBT_DEPLOYMENTS_WORKSPACES | F39: 2025-10-02 13:24:03.831 -0400
A40: MCP_SERVICE_ACCOUNT_TEMP | B40: SERVICE | C40: USERADMIN | D40: MCP_SERVICE_ACCOUNT_TEMP | E40: MCP_SERVICE_ACCOUNT_TEMP | F40: 2025-10-02 13:25:37.572 -0400
A41: GITHUB_ACTIONS_BUGSNAG_USER | B41: LEGACY_SERVICE | C41: USERADMIN | D41: BUGSNAG | E41: BUGSNAG | F41: 2025-10-02 14:03:11.584 -0400
...

Sheet Sigma
A1: User Name | B1: User Email | C1: License Type | D1: Account Type | E1: User Created at (UTC) | F1: Last Query Time (UTC) | G1: Days Since Last Query | H1: Invited By User Name | I1: Invited By User Email | J1: Invite Date (UTC) | K1: Account Permissions | L1: # Queries, Last 90 Days | M1: Teams | N1: # Teams | O1: Org Member Is Email Verified | P1: Should Downgrade | Q1: Should Delete | R1: Active Employee | S1: Notes | T1: Downgraded Permissions or Removed (If disabled for 90+ days, please remove)
A2: Exit Test 1 | B2: exit.test1@docker.com | C2: view | D2: View | E2: 45170.648 | H2: Fiona McShane | I2: fiona.mcshane@docker.com | J2: 45170.645 | K2: canComment, canDownloadLegacyDocs, canViewDashboard, canViewDatasetOrSql, canViewWorkbook, canViewWorksheet | L2: 0 | M2: All Members, Product | N2: 2 | O2: FALSE | Q2: Y | R2: =IF(COUNTIF('Active Employees'!B:B, B2)>0,"Y","N") -> N | S2: Test account
A3: Cheryl Lim | B3: Cheryl_lim@docker.com | C3: view | D3: View | E3: 45310.159 | H3: Zoey Kramer | I3: zoey.kramer@docker.com | J3: 45308.662 | K3: canComment, canDownloadLegacyDocs, canViewDashboard, canViewDatasetOrSql, canViewWorkbook, canViewWorksheet | L3: 0 | M3: All Members, Customer-Support | N3: 2 | O3: TRUE | Q3: Y | R3: =IF(COUNTIF('Active Employees'!B:B, B3)>0,"Y","N") -> N | S3: No queries
A4: Affandi Kamarolzaman | B4: affandi_kamarolzaman@docker.com | C4: view | D4: View | E4: 45799.775 | I4: [Invited via SAML] | K4: canComment, canDownloadLegacyDocs, canViewDashboard, canViewDatasetOrSql, canViewWorkbook, canViewWorksheet | L4: 0 | M4: All Members, Marketing | N4: 2 | O4: TRUE | Q4: Y | R4: =IF(COUNTIF('Active Employees'!B:B, B4)>0,"Y","N") -> N | S4: No queries
A5: Alex Salkever | B5: alex_salkever@docker.com | C5: view | D5: View | E5: 45854.891 | I5: [Invited via SAML] | K5: canComment, canDownloadLegacyDocs, canViewDashboard, canViewDatasetOrSql, canViewWorkbook, canViewWorksheet | L5: 0 | M5: All Members, Marketing | N5: 2 | O5: TRUE | Q5: Y | R5: =IF(COUNTIF('Active Employees'!B:B, B5)>0,"Y","N") -> N | S5: No queries
A6: Arlie Queenie | B6: arlie_queenie@docker.com | C6: view | D6: View | E6: 45799.775 | I6: [Invited via SAML] | K6: canComment, canDownloadLegacyDocs, canViewDashboard, canViewDatasetOrSql, canViewWorkbook, canViewWorksheet | L6: 0 | M6: All Members, Marketing | N6: 2 | O6: TRUE | Q6: Y | R6: =IF(COUNTIF('Active Employees'!B:B, B6)>0,"Y","N") -> N | S6: No queries
A7: Bjorn Hovd | B7: bjorn.hovd@docker.com | C7: view | D7: View | E7: 45922.38 | I7: [Invited via SAML] | K7: canComment, canDownloadLegacyDocs, canViewDashboard, canViewDatasetOrSql, canViewWorkbook, canViewWorksheet | L7: 0 | M7: All Members, Sales Team | N7: 2 | O7: TRUE | Q7: Y | R7: =IF(COUNTIF('Active Employees'!B:B, B7)>0,"Y","N") -> N | S7: No queries
A8: Blaine Wilson | B8: blaine.wilson@docker.com | C8: view | D8: View | E8: 45929.609 | I8: [Invited via SAML] | K8: canComment, canDownloadLegacyDocs, canViewDashboard, canViewDatasetOrSql, canViewWorkbook, canViewWorksheet | L8: 0 | M8: All Members, G&A | N8: 2 | O8: TRUE | Q8: Y | R8: =IF(COUNTIF('Active Employees'!B:B, B8)>0,"Y","N") -> N | S8: No queries
